Workbook

Sheet 進捗
B4: シート名 | H4: 試験件数 | U4: 進捗率 | AA4: 状態 | AF4: 全 | AH4: =SUM(J5:L28) -> 242 | AI4: 件
B5: =RIGHT(CELL("filename",ヒアーズミー!A2),LEN(CELL("filename",ヒアーズミー!A2))-FIND("]",CELL("filename",ヒアーズミー!A2))) -> ヒアーズミー | H5: 高 | J5: =ヒアーズミー!$F$4 -> 50 | M5: OK | P5: 高 | R5: =ヒアーズミー!$H$4 -> 50 | U5: 高 | W5: =IF(J5=0,"",R5/J5) -> 1 | Y5: =SUM(R5:T7)/SUM(J5:L10) -> 1 | AA5: =IF(Y5=100%,"完了","実施中") -> 完了 | AF5: 実施済み | AG5: OK | AH5: =SUM(R5:T7,R11:T13,R17:T19,R23:T25) -> 242 | AI5: 件 | AK5: 合計
P6: 中 | R6: =ヒアーズミー!$H$5 -> 0 | AG6: NG | AH6: =SUM(R8:T10,R14:T16,R20:T22,R26:T28) -> 0 | AI6: 件 | AK6: =SUM(AH5:AH6) -> 242 | AL6: 件
H7: 中 | J7: =ヒアーズミー!$F$5 -> 0 | P7: 低 | R7: =ヒアーズミー!$H$6 -> 0 | U7: 中 | W7: =IF(J7=0,"",R6/J7) | AK7: 進捗率
M8: NG | P8: 高 | R8: =ヒアーズミー!$I$4 -> 0 | AK8: =AH5/AH4 -> 1
H9: 低 | J9: =ヒアーズミー!$F$6 -> 0 | P9: 中 | R9: =ヒアーズミー!$I$5 -> 0 | U9: 低 | W9: =IF(J9=0,"",R7/J9)
P10: 低 | R10: =ヒアーズミー!$I$6 -> 0
B11: =RIGHT(CELL("filename",'管理ツール（IP制限機能）'!A2),LEN(CELL("filename",'管理ツール（IP制限機能）'!A2))-FIND("]",CELL("filename",'管理ツール（IP制限機能）'!A2))) -> 管理ツール（IP制限機能） | H11: 高 | J11: ='管理ツール（IP制限機能）'!$F$4 -> 103 | M11: OK | P11: 高 | R11: ='管理ツール（IP制限機能）'!H4 -> 103 | U11: 高 | W11: =IF(J11=0,"",R11/J11) -> 1 | Y11: =SUM(R11:T13)/SUM(J11:L16) -> 1 | AA11: =IF(Y11=100%,"完了","実施中") -> 完了
P12: 中 | R12: ='管理ツール（IP制限機能）'!H5 -> 0
H13: 中 | J13: ='管理ツール（IP制限機能）'!$F$5 -> 0 | P13: 低 | R13: ='管理ツール（IP制限機能）'!H6 -> 0 | U13: 中 | W13: =IF(J13=0,"",R12/J13)
M14: NG | P14: 高 | R14: ='管理ツール（IP制限機能）'!I4 -> 0
H15: 低 | J15: ='管理ツール（IP制限機能）'!$F$6 -> 0 | P15: 中 | R15: ='管理ツール（IP制限機能）'!I5 -> 0 | U15: 低 | W15: =IF(J15=0,"",R13/J15)
P16: 低 | R16: ='管理ツール（IP制限機能）'!I6 -> 0
B17: =RIGHT(CELL("filename",'管理ツール（ユーザ一括登録）'!A8),LEN(CELL("filename",'管理ツール（ユーザ一括登録）'!A8))-FIND("]",CELL("filename",'管理ツール（ユーザ一括登録）'!A8))) -> 管理ツール（ユーザ一括登録） | H17: 高 | J17: ='管理ツール（ユーザ一括登録）'!$F$4 -> 81 | M17: OK | P17: 高 | R17: ='管理ツール（ユーザ一括登録）'!$H$4 -> 81 | U17: 高 | W17: =IF(J17=0,"",R17/J17) -> 1 | Y17: =SUM(R17:T19)/SUM(J17:L22) -> 1 | AA17: =IF(Y17=100%,"完了","実施中") -> 完了
P18: 中 | R18: ='管理ツール（ユーザ一括登録）'!$H$5 -> 0
H19: 中 | J19: ='管理ツール（ユーザ一括登録）'!$F$5 -> 0 | P19: 低 | R19: ='管理ツール（ユーザ一括登録）'!$H$6 -> 0 | U19: 中 | W19: =IF(J19=0,"",R18/J19)
M20: NG | P20: 高 | R20: ='管理ツール（ユーザ一括登録）'!$I$4 -> 0
H21: 低 | J21: ='管理ツール（ユーザ一括登録）'!$F$6 -> 0 | P21: 中 | R21: ='管理ツール（ユーザ一括登録）'!$I$5 -> 0 | U21: 低 | W21: =IF(J21=0,"",R19/J21)
P22: 低 | R22: ='管理ツール（ユーザ一括登録）'!$I$6 -> 0
B23: =RIGHT(CELL("filename",アカウント作成ツール!A14),LEN(CELL("filename",アカウント作成ツール!A14))-FIND("]",CELL("filename",アカウント作成ツール!A14))) -> アカウント作成ツール | H23: 高 | J23: =アカウント作成ツール!$F$4 -> 8 | M23: OK | P23: 高 | R23: =アカウント作成ツール!$H$4 -> 8 | U23: 高 | W23: =IF(J23=0,"",R23/J23) -> 1 | Y23: =SUM(R23:T25)/SUM(J23:L28) -> 1 | AA23: =IF(Y23=100%,"完了","実施中") -> 完了
P24: 中 | R24: =アカウント作成ツール!$H$5 -> 0
H25: 中 | J25: =アカウント作成ツール!$F$5 -> 0 | P25: 低 | R25: =アカウント作成ツール!$H$6 -> 0 | U25: 中 | W25: =IF(J25=0,"",R24/J25)
M26: NG | P26: 高 | R26: =アカウント作成ツール!$I$4 -> 0
H27: 低 | J27: =アカウント作成ツール!$F$6 -> 0 | P27: 中 | R27: =アカウント作成ツール!$I$5 -> 0 | U27: 低 | W27: =IF(J27=0,"",R25/J27)
P28: 低 | R28: =アカウント作成ツール!$I$6 -> 0

Sheet ヒアーズミー
AB1: =SUM(H4,K4,N4,Q4,T4) -> 50
B2: システム名 | C2: ヒアーズミー(ver2.7) | D2: ■ヒアーズミーログイン画面(結合試験環境) | J2: 対象外数 | K2: =COUNTIF(J:J,"★") -> 0 | M2: 対象外数 | N2: =COUNTIF(M:M,"★") -> 0 | S2: 対象外数 | T2: =COUNTIF(S:S,"★") -> 0 | V2: 対象外数 | W2: =COUNTIF(V:V,"★") -> 0 | Y2: 対象外数 | Z2: =COUNTIF(Y:Y,"★") -> 0 | AB2: =SUM(H5,K5,N5,Q5,T5) -> 0
B3: 試験工程 | C3: 結合試験 | D3: https://heresme.micros-america.com/ | J3: 実施数 | K3: =SUM($F$4:$F$6)-K2 -> 50 | M3: 実施数 | N3: =SUM($F$4:$F$6)-N2 -> 50 | S3: 実施数 | T3: =SUM($F$4:$F$6)-T2 -> 50 | V3: 実施数 | W3: =SUM($F$4:$F$6)-W2 -> 50 | Y3: 実施数 | Z3: =SUM($F$4:$F$6)-Z2 -> 50 | AB3: =SUM(H6,K6,N6,Q6,T6) -> 0
B4: 試験項目名 | C4: ヒアーズミー | E4: 高 | F4: =COUNTIF($F$12:$F$212, "高") -> 50 | H4: =COUNTIFS($F12:$F212,"高",I12:I212,"OK")+COUNTIFS($F12:$F212,"高",I12:I212,"NG→OK") -> 50 | I4: =COUNTIFS($F12:$F212,"高",I12:I212,"NG") -> 0 | K4: =COUNTIFS($F12:$F212,"高",L12:L212,"OK") -> 0 | L4: =COUNTIFS($F12:$F212,"高",L12:L212,"NG") -> 0 | N4: =COUNTIFS($F12:$F212,"高",O12:O212,"OK")+COUNTIFS($F12:$F212,"高",O12:O212,"NG→OK") -> 0 | O4: =COUNTIFS($F12:$F212,"高",O12:O212,"NG") -> 0 | Q4: =COUNTIFS($F12:$F212,"高",R12:R212,"OK") -> 0 | R4: =COUNTIFS($F12:$F212,"高",R12:R212,"NG") -> 0 | T4: =COUNTIFS($F12:$F212,"高",U12:U212,"OK") -> 0 | U4: =COUNTIFS($F12:$F212,"高",U12:U212,"NG") -> 0 | W4: =COUNTIFS($F12:$F212,"高",X12:X212,"OK")+COUNTIFS($F12:$F212,"高",X12:X212,"NG→OK") -> 0 | X4: =COUNTIFS($F12:$F212,"高",X12:X212,"NG") -> 0 | Z4: =COUNTIFS($F12:$F212,"高",AA12:AA212,"OK") -> 0 | AA4: =COUNTIFS($F12:$F212,"高",AA12:AA212,"NG") -> 0 | AB4: =SUM(I4,L4,O4,R4,U4) -> 0
B5: 作成者 | C5: 神 洋子 | D5: ■試験実施バージョン | E5: 中 | F5: =COUNTIF($F$12:$F$212, "中") -> 0 | H5: =COUNTIFS($F12:$F212,"中",I12:I212,"OK") -> 0 | I5: =COUNTIFS($F12:$F212,"中",I12:I212,"NG") -> 0 | K5: =COUNTIFS($F12:$F212,"中",L12:L212,"OK") -> 0 | L5: =COUNTIFS($F12:$F212,"中",L12:L212,"NG") -> 0 | N5: =COUNTIFS($F12:$F212,"中",O12:O212,"OK")+COUNTIFS($F12:$F212,"中",O12:O212,"NG→OK") -> 0 | O5: =COUNTIFS($F12:$F212,"中",O12:O212,"NG") -> 0 | Q5: =COUNTIFS($F12:$F212,"中",R12:R212,"OK") -> 0 | R5: =COUNTIFS($F12:$F212,"中",R12:R212,"NG") -> 0 | T5: =COUNTIFS($F12:$F212,"中",U12:U212,"OK") -> 0 | U5: =COUNTIFS($F12:$F212,"中",U12:U212,"NG") -> 0 | W5: =COUNTIFS($F12:$F212,"中",X12:X212,"OK") -> 0 | X5: =COUNTIFS($F12:$F212,"中",X12:X212,"NG") -> 0 | Z5: =COUNTIFS($F12:$F212,"中",AA12:AA212,"OK") -> 0 | AA5: =COUNTIFS($F12:$F212,"中",AA12:AA212,"NG") -> 0 | AB5: =SUM(I5,L5,O5,R5,U5) -> 0
B6: 作成日 | C6: 44931 | D6: Chrome→★ 、 Firefox→★ | E6: 低 | F6: =COUNTIF($F$12:$F$212, "低") -> 0 | H6: =COUNTIFS($F12:$F212,"低",I12:I212,"OK") -> 0 | I6: =COUNTIFS($F12:$F212,"低",I12:I212,"NG") -> 0 | K6: =COUNTIFS($F12:$F212,"低",L12:L212,"OK") -> 0 | L6: =COUNTIFS($F12:$F212,"低",L12:L212,"NG") -> 0 | N6: =COUNTIFS($F12:$F212,"低",O12:O212,"OK") -> 0 | O6: =COUNTIFS($F12:$F212,"低",O12:O212,"NG") -> 0 | Q6: =COUNTIFS($F12:$F212,"低",R12:R212,"OK") -> 0 | R6: =COUNTIFS($F12:$F212,"低",R12:R212,"NG") -> 0 | T6: =COUNTIFS($F12:$F212,"低",U12:U212,"OK") -> 0 | U6: =COUNTIFS($F12:$F212,"低",U12:U212,"NG") -> 0 | W6: =COUNTIFS($F12:$F212,"低",X12:X212,"OK") -> 0 | X6: =COUNTIFS($F12:$F212,"低",X12:X212,"NG") -> 0 | Z6: =COUNTIFS($F12:$F212,"低",AA12:AA212,"OK") -> 0 | AA6: =COUNTIFS($F12:$F212,"低",AA12:AA212,"NG") -> 0 | AB6: =SUM(I6,L6,O6,R6,U6) -> 0
D7: IE→★ 、 Edge(chronium)→★
C8: 試験項目 | G8: Webブラウザ | V8: スマホアプリ
G9: Chrome | J9: Firefox | M9: edge(Chronium) | P9: edge(旧) | S9: IE | V9: Android | Y9: iOS
B10: No | C10: 試験条件 | D10: 試験手順 | E10: 確認内容 | F10: 優先度 | G10: 日付 | H10: 実施者 | I10: 結果 | J10: 日付 | K10: 実施者 | L10: 結果 | M10: 日付 | N10: 実施者 | O10: 結果 | P10: 日付 | Q10: 実施者 | R10: 結果 | S10: 日付 | T10: 実施者 | U10: 結果 | V10: 日付 | W10: 実施者 | X10: 結果 | Y10: 日付 | Z10: 実施者 | AA10: 結果
B11: 「データ（IP制限機能）」シート 【4】ログイン
B12: =IF($C$12:C12<>"",COUNTA($C$12:C12),"") -> 1 | C12: <PCブラウザ> クライアントバージョン：2.7.0 試験No1 ログイン方法→ID/パスワード入力 | D12: ① 「データ（IP制限機能）」シートの「実施条件」欄のDBデータを用意し、「リクエスト元IPアドレス」でヒアーズミーのログイン画面にアクセスする。 ② ログインアカウントを入力して「ログイン」ボタンをクリックする。 | E12: 「確認内容」の結果となることを確認する。 | F12: 高 | G12: 44942 | H12: 神(洋) | I12: OK
B13: =IF($C$12:C13<>"",COUNTA($C$12:C13),"") -> 2 | C13: <PCブラウザ> クライアントバージョン：2.7.0 試験No2 ログイン方法→ID/パスワード入力 | F13: 高 | G13: 44944 | H13: 神(洋) | I13: NG→OK
B14: =IF($C$12:C14<>"",COUNTA($C$12:C14),"") -> 3 | C14: <PCブラウザ> クライアントバージョン：2.7.0 試験No3 ログイン方法→ID/パスワード入力 | F14: 高 | G14: 44949 | H14: 神(洋) | I14: OK
B15: =IF($C$12:C15<>"",COUNTA($C$12:C15),"") -> 4 | C15: <PCブラウザ> クライアントバージョン：2.7.0 試験No4 ログイン方法→ID/パスワード入力 | F15: 高 | G15: 44949 | H15: 神(洋) | I15: OK
B16: =IF($C$12:C16<>"",COUNTA($C$12:C16),"") -> 5 | C16: <PCブラウザ> クライアントバージョン：2.7.0 試験No5 ログイン方法→ID/パスワード入力 | F16: 高 | G16: 44946 | H16: 神(洋) | I16: OK
B17: =IF($C$12:C17<>"",COUNTA($C$12:C17),"") -> 6 | C17: <PCブラウザ> クライアントバージョン：2.7.0 試験No6 ログイン方法→ID/パスワード入力 | F17: 高 | G17: 44946 | H17: 神(洋) | I17: OK
B18: =IF($C$12:C18<>"",COUNTA($C$12:C18),"") -> 7 | C18: <PCブラウザ> クライアントバージョン：2.7.0 試験No7 ログイン方法→ID/パスワード入力 | F18: 高 | G18: 44946 | H18: 神(洋) | I18: OK
B19: =IF($C$12:C19<>"",COUNTA($C$12:C19),"") -> 8 | C19: <PCブラウザ> クライアントバージョン：2.7.0 試験No8 ログイン方法→ID/パスワード入力 | F19: 高 | G19: 44946 | H19: 神(洋) | I19: OK
B20: =IF($C$12:C20<>"",COUNTA($C$12:C20),"") -> 9 | C20: <PCブラウザ> クライアントバージョン：2.7.0 試験No9 ログイン方法→ID/パスワード入力 | F20: 高 | G20: 44946 | H20: 神(洋) | I20: NG→OK
B21: =IF($C$12:C21<>"",COUNTA($C$12:C21),"") -> 10 | C21: <PCブラウザ> クライアントバージョン：2.7.0 試験No10 ログイン方法→ID/パスワード入力 | F21: 高 | G21: 44949 | H21: 神(洋) | I21: OK
B22: =IF($C$12:C22<>"",COUNTA($C$12:C22),"") -> 11 | C22: <PCブラウザ> クライアントバージョン：2.7.0 試験No11 ログイン方法→ID/パスワード入力 | F22: 高 | G22: 44949 | H22: 神(洋) | I22: OK
B23: =IF($C$12:C23<>"",COUNTA($C$12:C23),"") -> 12 | C23: <PCブラウザ> クライアントバージョン：2.7.0 試験No12 ログイン方法→ID/パスワード入力 | F23: 高 | G23: 44949 | H23: 神(洋) | I23: OK
B24: =IF($C$12:C24<>"",COUNTA($C$12:C24),"") -> 13 | C24: <PCブラウザ> クライアントバージョン：2.7.0 試験No13 ログイン方法→ID/パスワード入力 | F24: 高 | G24: 44949 | H24: 神(洋) | I24: OK
... B31: =IF($C$12:C31<>"",COUNTA($C$12:C31),"") -> 20 | C31: <PCブラウザ> クライアントバージョン：2.7.0 試験No20 ログイン方法→ID/パスワード入力 | F31: 高 | G31: 44949 | H31: 神(洋) | I31: OK
B32: =IF($C$12:C32<>"",COUNTA($C$12:C32),"") -> 21 | C32: <PCブラウザ（トークン）> クライアントバージョン：2.7.0 試験No1 ログイン方法→トークン | E32: メイン画面に遷移すること。 | F32: 高 | G32: 44942 | H32: 神(洋) | I32: OK
B33: =IF($C$12:C33<>"",COUNTA($C$12:C33),"") -> 22 | C33: <PCブラウザ（トークン）> クライアントバージョン：2.7.0 試験No2 ログイン方法→トークン | E33: メイン画面に遷移すること。 | F33: 高 | G33: 44949 | H33: 神(洋) | I33: OK
B34: =IF($C$12:C34<>"",COUNTA($C$12:C34),"") -> 23 | C34: <PCブラウザ（トークン）> クライアントバージョン：2.7.0 試験No12 ログイン方法→トークン | E34: エラーメッセージが表示され、メイン画面に遷移しないこと。 （メッセージからIP制限でエラーとなって事が分かるかどうか確認する） | F34: 高 | G34: 44949 | H34: 神(洋) | I34: OK
B35: =IF($C$12:C35<>"",COUNTA($C$12:C35),"") -> 24 | C35: <PCブラウザ（旧バージョン）> クライアントバージョン：2.6.3 試験No1 ログイン方法→任意 | E35: メイン画面に遷移すること。 | F35: 高 | G35: 44943 | H35: 神(洋) | I35: OK
B36: =IF($C$12:C36<>"",COUNTA($C$12:C36),"") -> 25 | C36: <PCブラウザ（旧バージョン）> クライアントバージョン：2.6.3 試験No2 ログイン方法→任意 | E36: メイン画面に遷移すること。 | F36: 高 | G36: 44943 | H36: 神(洋) | I36: OK
B37: =IF($C$12:C37<>"",COUNTA($C$12:C37),"") -> 26 | C37: <PCブラウザ（旧バージョン）> クライアントバージョン：2.6.3 試験No12 ログイン方法→任意 | E37: エラーメッセージが表示され、メイン画面に遷移しないこと。 （メッセージからIP制限でエラーとなって事が分かるかどうか確認する） | F37: 高 | G37: 44949 | H37: 神(洋) | I37: OK
B38: =IF($C$12:C38<>"",COUNTA($C$12:C38),"") -> 27 | C38: <Androidアプリ> クライアントバージョン：2.7.0 試験No1 ログイン方法→ID/パスワード | E38: メイン画面に遷移すること。 | F38: 高 | G38: 44949 | H38: 神(洋) | I38: OK
B39: =IF($C$12:C39<>"",COUNTA($C$12:C39),"") -> 28 | C39: <Androidアプリ> クライアントバージョン：2.7.0 試験No2 ログイン方法→ID/パスワード | E39: メイン画面に遷移すること。 | F39: 高 | G39: 44949 | H39: 神(洋) | I39: OK
B40: =IF($C$12:C40<>"",COUNTA($C$12:C40),"") -> 29 | C40: <Androidアプリ> クライアントバージョン：2.7.0 試験No12 ログイン方法→ID/パスワード | E40: IP制限エラーのメッセージが表示され、メイン画面に遷移しないこと。 | F40: 高 | G40: 44949 | H40: 神(洋) | I40: OK
B41: =IF($C$12:C41<>"",COUNTA($C$12:C41),"") -> 30 | C41: <Androidアプリ(トークン)> クライアントバージョン：2.7.0 試験No1 ログイン方法→トークン | E41: メイン画面に遷移すること。 | F41: 高 | G41: 44949 | H41: 神(洋) | I41: OK
B42: =IF($C$12:C42<>"",COUNTA($C$12:C42),"") -> 31 | C42: <Androidアプリ(トークン)> クライアントバージョン：2.7.0 試験No2 ログイン方法→トークン | E42: メイン画面に遷移すること。 | F42: 高 | G42: 44949 | H42: 神(洋) | I42: OK
B43: =IF($C$12:C43<>"",COUNTA($C$12:C43),"") -> 32 | C43: <Androidアプリ(トークン)> クライアントバージョン：2.7.0 試験No12 ログイン方法→トークン | E43: IP制限エラーのメッセージが表示され、メイン画面に遷移しないこと。 | F43: 高 | G43: 44949 | H43: 神(洋) | I43: OK
... B52: =IF($C$12:C52<>"",COUNTA($C$12:C52),"") -> 41 | C52: <iOSアプリ（旧バージョン）> クライアントバージョン：2.6.3 試験No12 ログイン方法→任意 | E52: エラーメッセージが表示され、メイン画面に遷移しないこと。 （メッセージからIP制限でエラーとなって事が分かるかどうか確認する） | F52: 高 | G52: 44950 | H52: 神(洋) | I52: OK
B53: =IF($C$12:C53<>"",COUNTA($C$12:C53),"")
B54: バージョンチェック
...

Sheet 管理ツール（IP制限機能）
V1: =SUM(H4,K4,N4,Q4,T4) -> 103
B2: システム名 | C2: ヒアーズミー(ver2.7) | D2: ■Here's Meログイン画面(結合試験環境) | J2: 対象外数 | K2: =COUNTIF(J:J,"★") -> 0 | M2: 対象外数 | N2: =COUNTIF(M:M,"★") -> 0 | S2: 対象外数 | T2: =COUNTIF(S:S,"★") -> 0 | V2: =SUM(H5,K5,N5,Q5,T5) -> 0
B3: 試験工程 | C3: 結合試験 | D3: https://heresme.micros-america.com/ | J3: 実施数 | K3: =SUM($F$4:$F$6)-K2 -> 103 | M3: 実施数 | N3: =SUM($F$4:$F$6)-N2 -> 103 | S3: 実施数 | T3: =SUM($F$4:$F$6)-T2 -> 103 | V3: =SUM(H6,K6,N6,Q6,T6) -> 0
B4: 試験項目名 | C4: 管理ツール | E4: 高 | F4: =COUNTIF($F$12:$F$282, "高") -> 103 | H4: =COUNTIFS($F12:$F282,"高",I12:I282,"OK")+COUNTIFS($F12:$F282,"高",I12:I282,"NG→OK") -> 103 | I4: =COUNTIFS($F12:$F282,"高",I12:I282,"NG") -> 0 | K4: =COUNTIFS($F12:$F282,"高",L12:L282,"OK") -> 0 | L4: =COUNTIFS($F12:$F282,"高",L12:L282,"NG") -> 0 | N4: =COUNTIFS($F12:$F282,"高",O12:O282,"OK")+COUNTIFS($F12:$F282,"高",O12:O282,"NG→OK") -> 0 | O4: =COUNTIFS($F12:$F282,"高",O12:O282,"NG") -> 0 | Q4: =COUNTIFS($F12:$F282,"高",R12:R282,"OK") -> 0 | R4: =COUNTIFS($F12:$F282,"高",R12:R282,"NG") -> 0 | T4: =COUNTIFS($F12:$F282,"高",U12:U282,"OK") -> 0 | U4: =COUNTIFS($F12:$F282,"高",U12:U282,"NG") -> 0 | V4: =SUM(I4,L4,O4,R4,U4) -> 0
B5: 作成者 | C5: 神 洋子 | D5: ■試験実施バージョン | E5: 中 | F5: =COUNTIF($F$12:$F$282, "中") -> 0 | H5: =COUNTIFS($F12:$F282,"中",I12:I282,"OK") -> 0 | I5: =COUNTIFS($F12:$F282,"中",I12:I282,"NG") -> 0 | K5: =COUNTIFS($F12:$F282,"中",L12:L282,"OK") -> 0 | L5: =COUNTIFS($F12:$F282,"中",L12:L282,"NG") -> 0 | N5: =COUNTIFS($F12:$F282,"中",O12:O282,"OK")+COUNTIFS($F12:$F282,"中",O12:O282,"NG→OK") -> 0 | O5: =COUNTIFS($F12:$F282,"中",O12:O282,"NG") -> 0 | Q5: =COUNTIFS($F12:$F282,"中",R12:R282,"OK") -> 0 | R5: =COUNTIFS($F12:$F282,"中",R12:R282,"NG") -> 0 | T5: =COUNTIFS($F12:$F282,"中",U12:U282,"OK") -> 0 | U5: =COUNTIFS($F12:$F282,"中",U12:U282,"NG") -> 0 | V5: =SUM(I5,L5,O5,R5,U5) -> 0
B6: 作成日 | C6: 44936 | D6: Chrome→★ 、 Firefox→★ | E6: 低 | F6: =COUNTIF($F$12:$F$282, "低") -> 0 | H6: =COUNTIFS($F12:$F282,"低",I12:I282,"OK") -> 0 | I6: =COUNTIFS($F12:$F282,"低",I12:I282,"NG") -> 0 | K6: =COUNTIFS($F12:$F282,"低",L12:L282,"OK") -> 0 | L6: =COUNTIFS($F12:$F282,"低",L12:L282,"NG") -> 0 | N6: =COUNTIFS($F12:$F282,"低",O12:O282,"OK") -> 0 | O6: =COUNTIFS($F12:$F282,"低",O12:O282,"NG") -> 0 | Q6: =COUNTIFS($F12:$F282,"低",R12:R282,"OK") -> 0 | R6: =COUNTIFS($F12:$F282,"低",R12:R282,"NG") -> 0 | T6: =COUNTIFS($F12:$F282,"低",U12:U282,"OK") -> 0 | U6: =COUNTIFS($F12:$F282,"低",U12:U282,"NG") -> 0 | V6: =SUM(I6,L6,O6,R6,U6) -> 0
D7: IE→★ 、 Edge(chronium)→★
C8: 試験項目 | G8: Webブラウザ
G9: １回目（Chrome） | J9: Firefox | M9: edge(Chronium) | P9: edge(旧) | S9: IE
B10: No | C10: 試験条件 | D10: 試験手順 | E10: 確認内容 | F10: 優先度 | G10: 日付 | H10: 実施者 | I10: 結果 | J10: 日付 | K10: 実施者 | L10: 結果 | M10: 日付 | N10: 実施者 | O10: 結果 | P10: 日付 | Q10: 実施者 | R10: 結果 | S10: 日付 | T10: 実施者 | U10: 結果
B11: メニュー
B12: =IF($C$12:C12<>"",COUNTA($C$12:C12),"") -> 1 | C12: メニュー「ユーザ管理」 | D12: ① ヒアーズミー管理ツールにログインする。 ② 試験条件のメニューをクリックする。 | E12: 試験条件の画面が表示され、メニュー見出し「設定」の中に「セキュリティ」が存在していることを確認する。 | F12: 高 | G12: 44943 | H12: 神(洋) | I12: OK
B13: =IF($C$12:C13<>"",COUNTA($C$12:C13),"") -> 2 | C13: メニュー「一括登録」 | F13: 高 | G13: 44943 | H13: 神(洋) | I13: OK
B14: =IF($C$12:C14<>"",COUNTA($C$12:C14),"") -> 3 | C14: メニュー「拠点」 | F14: 高 | G14: 44943 | H14: 神(洋) | I14: OK
B15: =IF($C$12:C15<>"",COUNTA($C$12:C15),"") -> 4 | C15: メニュー「所属」 | F15: 高 | G15: 44943 | H15: 神(洋) | I15: OK
B16: =IF($C$12:C16<>"",COUNTA($C$12:C16),"") -> 5 | C16: メニュー「役職」 | F16: 高 | G16: 44943 | H16: 神(洋) | I16: OK
B17: =IF($C$12:C17<>"",COUNTA($C$12:C17),"") -> 6 | C17: メニュー「行先」 | F17: 高 | G17: 44943 | H17: 神(洋) | I17: OK
B18: =IF($C$12:C18<>"",COUNTA($C$12:C18),"") -> 7 | C18: メニュー「状態」 | F18: 高 | G18: 44943 | H18: 神(洋) | I18: OK
B19: =IF($C$12:C19<>"",COUNTA($C$12:C19),"") -> 8 | C19: メニュー「勤怠データ」 | F19: 高 | G19: 44943 | H19: 神(洋) | I19: OK
B20: =IF($C$12:C20<>"",COUNTA($C$12:C20),"") -> 9 | C20: メニュー「管理アカウント」 | F20: 高 | G20: 44943 | H20: 神(洋) | I20: OK
B21: =IF($C$12:C21<>"",COUNTA($C$12:C21),"") -> 10 | C21: メニュー「セキュリティ」 | F21: 高 | G21: 44943 | H21: 神(洋) | I21: OK
B22: =IF($C$12:C22<>"",COUNTA($C$12:C22),"") -> 11 | C22: メニュー「導入手順書」 | E22: 導入手順書をダウンロードできることを確認する。 | F22: 高 | G22: 44943 | H22: 神(洋) | I22: OK
B23: =IF($C$12:C23<>"",COUNTA($C$12:C23),"")
B24: 「セキュリティ」画面 表示・操作
B25: =IF($C$12:C25<>"",COUNTA($C$12:C25),"") -> 12 | C25: リクエスト元IPアドレス表示 | D25: ① ヒアーズミー管理ツールの「セキュリティ」画面を開く。 | E25: 見出し「IPアドレス制限」の右側に、リクエスト元IPアドレスが表示されていることを確認する。 ※リクエスト元IPアドレスは以下のページで確認 https://www.cman.jp/network/support/go_access.cgi | F25: 高 | G25: 44943 | H25: 神(洋) | I25: OK
B26: =IF($C$12:C26<>"",COUNTA($C$12:C26),"") -> 13 | C26: 「ヒアーズミーにアクセスするIPアドレスを制限」チェックボックス操作 | D26: ① ヒアーズミー管理ツールの「セキュリティ」画面を開く。 ② 「ヒアーズミーにアクセスするIPアドレスを制限」チェックボックスのON/OFFを切り替える。 | E26: チェックボックスをONにすると、「許可するIPアドレス」入力フォームが入力可能となり、OFFにすると入力フォームが入力不可（グレー）になることを確認。 | F26: 高 | G26: 44943 | H26: 神(洋) | I26: OK
B27: =IF($C$12:C27<>"",COUNTA($C$12:C27),"") -> 14 | C27: 「許可するIPアドレス」リスト ×ボタン操作 | D27: ① ヒアーズミー管理ツールの「セキュリティ」画面を開く。 ② 「許可するIPアドレスリスト」で、IPアドレス・名称が入力されている行の×ボタンをクリックする。 | E27: ×ボタンをクリックした行のIPアドレス・名称欄がクリアされることを確認。 | F27: 高 | G27: 44943 | H27: 神(洋) | I27: OK
B28: =IF($C$12:C28<>"",COUNTA($C$12:C28),"") -> 15 | C28: 「許可するIPアドレス」リスト ×ボタン操作 | D28: ① ヒアーズミー管理ツールの「セキュリティ」画面を開く。 ② 「許可するIPアドレスリスト」で、IPアドレスのみが入力されている行の×ボタンをクリックする。 | E28: ×ボタンをクリックした行のIPアドレス・名称欄がクリアされることを確認。 | F28: 高 | G28: 44943 | H28: 神(洋) | I28: OK
B29: =IF($C$12:C29<>"",COUNTA($C$12:C29),"") -> 16 | C29: 「許可するIPアドレス」リスト ×ボタン操作 | D29: ① ヒアーズミー管理ツールの「セキュリティ」画面を開く。 ② 「許可するIPアドレスリスト」で、名称のみが入力されている行の×ボタンをクリックする。 | E29: ×ボタンをクリックした行のIPアドレス・名称欄がクリアされることを確認。 | F29: 高 | G29: 44943 | H29: 神(洋) | I29: OK
B30: =IF($C$12:C30<>"",COUNTA($C$12:C30),"") -> 17 | C30: 「許可するIPアドレス」リスト 「＋」(追加)ボタン操作 （IP設定可能数：20） | D30: ① ヒアーズミー管理ツールの「セキュリティ」画面を開く。 ② 「許可するIPアドレスリスト」が19個以下の状態で「＋」(追加)ボタンを１回クリックする。 | E30: リストの最後尾に空き行が１行追加されることを確認。 行頭の番号は、追加前の最後尾の番号＋１であること。 | F30: 高 | G30: 44943 | H30: 神(洋) | I30: OK
B31: =IF($C$12:C31<>"",COUNTA($C$12:C31),"") -> 18 | C31: 「許可するIPアドレス」リスト 「＋」(追加)ボタン操作 （IP設定可能数：20） | D31: ① ヒアーズミー管理ツールの「セキュリティ」画面を開く。 ② 「許可するIPアドレスリスト」が20個の状態で「＋」(追加)ボタンを１回クリックする。 | E31: 行追加できない旨のメッセージが表示され、リストの最後尾に空き行が追加されないことを確認。 | F31: 高 | G31: 44943 | H31: 神(洋) | I31: OK
B32: =IF($C$12:C32<>"",COUNTA($C$12:C32),"") -> 19 | C32: 「許可するIPアドレス」リスト 「＋」(追加)ボタン操作 （IP設定可能数：10） ※レビュー指摘で追加 | D32: ① ヒアーズミー管理ツールの「セキュリティ」画面を開く。 ② 「＋」(追加)ボタンをクリックし、空き行含めて10行まで増やす。 ③ 10行の状態からさらに「＋」(追加)ボタンをクリックする。 | E32: 行追加できない旨のメッセージが表示され、リストの最後尾に空き行が追加されないことを確認。 | F32: 高 | G32: 44943 | H32: 神(洋) | I32: OK
B33: =IF($C$12:C33<>"",COUNTA($C$12:C33),"") -> 20 | C33: 「許可するIPアドレス」リスト 「＋」(追加)ボタン操作 （IP設定可能数：30） ※レビュー指摘で追加 | D33: ① ヒアーズミー管理ツールの「セキュリティ」画面を開く。 ② 「＋」(追加)ボタンをクリックし、空き行含めて30行まで増やす。 ③ 30行の状態からさらに「＋」(追加)ボタンをクリックする。 | E33: 行追加できない旨のメッセージが表示され、リストの最後尾に空き行が追加されないことを確認。 | F33: 高 | G33: 44943 | H33: 神(洋) | I33: OK
B34: =IF($C$12:C34<>"",COUNTA($C$12:C34),"") -> 21 | C34: サーバ保存確認ダイアログ | D34: ① ヒアーズミー管理ツールの「セキュリティ」画面を開く。 ② 「許可するIPアドレス」をエラーにならないように変更し、「サーバ保存」ボタンをクリックする。 | E34: サーバ保存確認ダイアログが表示されることを確認。 ---------- IPアドレス制限設定を保存します。よろしいですか？ ※チェックを外した場合、以前設定したIPアドレスリストは削除されます。 「OK」「キャンセル」 | F34: 高 | G34: 44943 | H34: 神(洋) | I34: OK
B35: =IF($C$12:C35<>"",COUNTA($C$12:C35),"") -> 22 | C35: サーバ保存確認ダイアログ | D35: ① サーバ保存確認ダイアログを表示する。 ② サーバ保存確認ダイアログの「OK」ボタンをクリックする。 | E35: サーバ保存確認ダイアログが閉じ、サーバ保存完了ダイアログが表示されることを確認。 変更内容がDBに反映されていることを確認。 ---------- 保存しました。 「OK」 | F35: 高 | G35: 44943 | H35: 神(洋) | I35: OK
B36: =IF($C$12:C36<>"",COUNTA($C$12:C36),"") -> 23 | C36: サーバ保存確認ダイアログ | D36: ① サーバ保存確認ダイアログを表示する。 ② サーバ保存確認ダイアログの「キャンセル」ボタンをクリックする。 | E36: サーバ保存確認ダイアログが閉じることを確認。 DBに変更がないことを確認。 | F36: 高 | G36: 44943 | H36: 神(洋) | I36: OK
... B42: =IF($C$12:C42<>"",COUNTA($C$12:C42),"") -> 29 | C42: 変更を保存せず別画面へ | D42: ① ヒアーズミー管理ツールの「セキュリティ」画面を開く。 ② 設定内容を任意で変更し、サーバ保存しないまま別画面のメニューをクリックする。 | E42: 保存未完了のメッセージ（ブラウザのメッセージ）が表示されることを確認。 | F42: 高 | G42: 44943 | H42: 神(洋) | I42: OK
B43: =IF($C$12:C43<>"",COUNTA($C$12:C43),"")
B44: サーバ結果正常以外
B45: =IF($C$12:C45<>"",COUNTA($C$12:C45),"") -> 30 | C45: IP制限設定取得 （コマンド：REQ_SEL_IPMNG） | D45: ① DBテーブル「iw_ipmanagetbl」のデータのうち、ログインする企業の「company_id」の値を変更する。 ② ヒアーズミー管理ツールにログインする。 ③ ヒアーズミー管理ツールの「セキュリティ」画面を開く。 | E45: ②実施後、正常にログインでいることを確認する。（ip_managetblのデータがないのは、ログイン時にはIP制限なしとみなす） ③実施後、サーバ処理エラーのアラートが表示されることを確認。 ------- サーバ処理でエラーが発生しました。 (REQ_SEL_IPMNG/エラーコード) | F45: 高 | G45: 44949 | H45: 神(洋) | I45: OK
...

Sheet 管理ツール（ユーザ一括登録）
V1: =SUM(H4,K4,N4,Q4,T4) -> 81
B2: システム名 | C2: ヒアーズミー(ver2.7) | D2: ■Here's Meログイン画面(結合試験環境) | J2: 対象外数 | K2: =COUNTIF(J:J,"★") -> 0 | M2: 対象外数 | N2: =COUNTIF(M:M,"★") -> 0 | S2: 対象外数 | T2: =COUNTIF(S:S,"★") -> 0 | V2: =SUM(H5,K5,N5,Q5,T5) -> 0
B3: 試験工程 | C3: 結合試験 | D3: https://heresme.micros-america.com/ | J3: 実施数 | K3: =SUM($F$4:$F$6)-K2 -> 81 | M3: 実施数 | N3: =SUM($F$4:$F$6)-N2 -> 81 | S3: 実施数 | T3: =SUM($F$4:$F$6)-T2 -> 81 | V3: =SUM(H6,K6,N6,Q6,T6) -> 0
B4: 試験項目名 | C4: 管理ツール | E4: 高 | F4: =COUNTIF($F$12:$F$251, "高") -> 81 | H4: =COUNTIFS($F12:$F251,"高",I12:I251,"OK")+COUNTIFS($F12:$F251,"高",I12:I251,"NG→OK") -> 81 | I4: =COUNTIFS($F12:$F251,"高",I12:I251,"NG") -> 0 | K4: =COUNTIFS($F12:$F251,"高",L12:L251,"OK") -> 0 | L4: =COUNTIFS($F12:$F251,"高",L12:L251,"NG") -> 0 | N4: =COUNTIFS($F12:$F251,"高",O12:O251,"OK")+COUNTIFS($F12:$F251,"高",O12:O251,"NG→OK") -> 0 | O4: =COUNTIFS($F12:$F251,"高",O12:O251,"NG") -> 0 | Q4: =COUNTIFS($F12:$F251,"高",R12:R251,"OK") -> 0 | R4: =COUNTIFS($F12:$F251,"高",R12:R251,"NG") -> 0 | T4: =COUNTIFS($F12:$F251,"高",U12:U251,"OK") -> 0 | U4: =COUNTIFS($F12:$F251,"高",U12:U251,"NG") -> 0 | V4: =SUM(I4,L4,O4,R4,U4) -> 0
B5: 作成者 | C5: 神 洋子 | D5: ■試験実施バージョン | E5: 中 | F5: =COUNTIF($F$12:$F$251, "中") -> 0 | H5: =COUNTIFS($F12:$F251,"中",I12:I251,"OK") -> 0 | I5: =COUNTIFS($F12:$F251,"中",I12:I251,"NG") -> 0 | K5: =COUNTIFS($F12:$F251,"中",L12:L251,"OK") -> 0 | L5: =COUNTIFS($F12:$F251,"中",L12:L251,"NG") -> 0 | N5: =COUNTIFS($F12:$F251,"中",O12:O251,"OK")+COUNTIFS($F12:$F251,"中",O12:O251,"NG→OK") -> 0 | O5: =COUNTIFS($F12:$F251,"中",O12:O251,"NG") -> 0 | Q5: =COUNTIFS($F12:$F251,"中",R12:R251,"OK") -> 0 | R5: =COUNTIFS($F12:$F251,"中",R12:R251,"NG") -> 0 | T5: =COUNTIFS($F12:$F251,"中",U12:U251,"OK") -> 0 | U5: =COUNTIFS($F12:$F251,"中",U12:U251,"NG") -> 0 | V5: =SUM(I5,L5,O5,R5,U5) -> 0
B6: 作成日 | C6: 44936 | D6: Chrome→★ 、 Firefox→★ | E6: 低 | F6: =COUNTIF($F$12:$F$251, "低") -> 0 | H6: =COUNTIFS($F12:$F251,"低",I12:I251,"OK") -> 0 | I6: =COUNTIFS($F12:$F251,"低",I12:I251,"NG") -> 0 | K6: =COUNTIFS($F12:$F251,"低",L12:L251,"OK") -> 0 | L6: =COUNTIFS($F12:$F251,"低",L12:L251,"NG") -> 0 | N6: =COUNTIFS($F12:$F251,"低",O12:O251,"OK") -> 0 | O6: =COUNTIFS($F12:$F251,"低",O12:O251,"NG") -> 0 | Q6: =COUNTIFS($F12:$F251,"低",R12:R251,"OK") -> 0 | R6: =COUNTIFS($F12:$F251,"低",R12:R251,"NG") -> 0 | T6: =COUNTIFS($F12:$F251,"低",U12:U251,"OK") -> 0 | U6: =COUNTIFS($F12:$F251,"低",U12:U251,"NG") -> 0 | V6: =SUM(I6,L6,O6,R6,U6) -> 0
D7: IE→★ 、 Edge(chronium)→★
C8: 試験項目 | G8: Webブラウザ
G9: Chrome | J9: Firefox | M9: edge(Chronium) | P9: edge(旧) | S9: IE
B10: No | C10: 試験条件 | D10: 試験手順 | E10: 確認内容 | F10: 優先度 | G10: 日付 | H10: 実施者 | I10: 結果 | J10: 日付 | K10: 実施者 | L10: 結果 | M10: 日付 | N10: 実施者 | O10: 結果 | P10: 日付 | Q10: 実施者 | R10: 結果 | S10: 日付 | T10: 実施者 | U10: 結果
B11: メニュー
B12: =IF($C$12:C12<>"",COUNTA($C$12:C12),"") -> 1 | C12: メニュー「ユーザ管理」 | D12: ① ヒアーズミー管理ツールにログインする。 ② 試験条件のメニューをクリックする。 | E12: 試験条件の画面が表示され、メニュー見出し「ユーザ管理」の中に「一括登録」が存在していることを確認する。 | F12: 高 | G12: 44943 | H12: 神(洋) | I12: OK
B13: =IF($C$12:C13<>"",COUNTA($C$12:C13),"") -> 2 | C13: メニュー「一括登録」 | F13: 高 | G13: 44943 | H13: 神(洋) | I13: OK
B14: =IF($C$12:C14<>"",COUNTA($C$12:C14),"") -> 3 | C14: メニュー「拠点」 | F14: 高 | G14: 44943 | H14: 神(洋) | I14: OK
B15: =IF($C$12:C15<>"",COUNTA($C$12:C15),"") -> 4 | C15: メニュー「所属」 | F15: 高 | G15: 44943 | H15: 神(洋) | I15: OK
B16: =IF($C$12:C16<>"",COUNTA($C$12:C16),"") -> 5 | C16: メニュー「役職」 | F16: 高 | G16: 44943 | H16: 神(洋) | I16: OK
B17: =IF($C$12:C17<>"",COUNTA($C$12:C17),"") -> 6 | C17: メニュー「行先」 | F17: 高 | G17: 44943 | H17: 神(洋) | I17: OK
B18: =IF($C$12:C18<>"",COUNTA($C$12:C18),"") -> 7 | C18: メニュー「状態」 | F18: 高 | G18: 44943 | H18: 神(洋) | I18: OK
B19: =IF($C$12:C19<>"",COUNTA($C$12:C19),"") -> 8 | C19: メニュー「勤怠データ」 | F19: 高 | G19: 44943 | H19: 神(洋) | I19: OK
B20: =IF($C$12:C20<>"",COUNTA($C$12:C20),"") -> 9 | C20: メニュー「管理アカウント」 | F20: 高 | G20: 44943 | H20: 神(洋) | I20: OK
B21: =IF($C$12:C21<>"",COUNTA($C$12:C21),"") -> 10 | C21: メニュー「セキュリティ」 | F21: 高 | G21: 44943 | H21: 神(洋) | I21: OK
B22: =IF($C$12:C22<>"",COUNTA($C$12:C22),"")
B23: 「一括登録」画面 表示・操作
B24: =IF($C$12:C24<>"",COUNTA($C$12:C24),"") -> 11 | C24: 初期表示 | D24: ① ヒアーズミー管理ツールの「一括登録」画面を開く。 | E24: 「ファイルを選択」ボタンの横に「ファイルを選択してください」と表示され、「チェック開始」ボタンがグレー（クリック不可）となっていることを確認。 | F24: 高 | G24: 44956 | H24: 神(洋) | I24: OK
B25: =IF($C$12:C25<>"",COUNTA($C$12:C25),"") -> 12 | C25: ファイル再選択 | D25: ① ヒアーズミー管理ツールの「一括登録」画面を開く。 ② 任意のcsvファイルを選択して「チェック開始」を実行する。 ③ チェック結果が表示された後、ファイル名、内容ともに異なるcsvファイルを選択して、再度「チェック開始」を実行する。 | E25: ③で選択したファイルの内容でチェックが実行されることを確認する。 | F25: 高 | G25: 44956 | H25: 神(洋) | I25: OK
B26: =IF($C$12:C26<>"",COUNTA($C$12:C26),"") -> 13 | C26: ファイル再選択 | D26: ① ヒアーズミー管理ツールの「一括登録」画面を開く。 ② 任意のcsvファイルを選択して「チェック開始」を実行する。 ③ チェック結果が表示された後、ファイル名は②と同一で、内容が異なるcsvファイルを選択して、再度「チェック開始」を実行する。 | E26: ③で選択したファイルの内容でチェックが実行されることを確認する。 | F26: 高 | G26: 44957 | H26: 神(洋) | I26: NG→OK
B27: =IF($C$12:C27<>"",COUNTA($C$12:C27),"") -> 14 | C27: ファイル再選択 | D27: ① ヒアーズミー管理ツールの「一括登録」画面を開く。 ② 任意のcsvファイルを選択して「チェック開始」を実行する。 ③ チェック結果が表示された後、ファイル拡張子が不正（.txtなど）のファイルを選択する。 | E27: ③実施後、②で表示されたチェック結果表示エリアが非表示になり、「一括登録」画面を開いた時と同じ状態になることを確認する。 「チェック開始」ボタンをクリックできないことを確認する。 | F27: 高 | G27: 44956 | H27: 神(洋) | I27: OK
B28: =IF($C$12:C28<>"",COUNTA($C$12:C28),"") -> 15 | C28: チェック開始確認ダイアログ | D28: ① ヒアーズミー管理ツールの「一括登録」画面を開く。 ② 任意のcsvファイルを選択して「チェック開始」をクリックする。 | E28: チェック開始確認ダイアログが表示されることを確認。 ---------- インポートするCSVファイルのチェックを開始します。よろしいですか？ 「OK」「キャンセル」 | F28: 高 | G28: 44956 | H28: 神(洋) | I28: OK
B29: =IF($C$12:C29<>"",COUNTA($C$12:C29),"") -> 16 | C29: チェック開始確認ダイアログ | D29: ① ヒアーズミー管理ツールの「一括登録」画面を開く。 ② 任意のcsvファイルを選択して「チェック開始」をクリックする。 ③ チェック開始確認ダイアログの「キャンセル」ボタンをクリックする。 | E29: チェック開始確認ダイアログが閉じることを確認。 チェック結果表が表示されないことを確認。 | F29: 高 | G29: 44956 | H29: 神(洋) | I29: OK
B30: =IF($C$12:C30<>"",COUNTA($C$12:C30),"") -> 17 | C30: チェック完了ダイアログ （エラー・要確認なし） | D30: ① ヒアーズミー管理ツールの「一括登録」画面を開く。 ② エラーや要確認を含まないcsvファイルを選択して「チェック開始」をクリックしてチェック開始確認ダイアログを開く。 ③ チェック開始確認ダイアログの「OK」ボタンをクリックする。 | E30: チェック開始確認ダイアログが閉じ、チェック完了ダイアログが表示されることを確認。 ---------- CSVファイルのチェックが完了しました。 サーバ保存ボタンをクリックしてください。 「OK」 | F30: 高 | G30: 44957 | H30: 神(洋) | I30: OK
B31: =IF($C$12:C31<>"",COUNTA($C$12:C31),"") -> 18 | C31: チェック完了ダイアログ （エラー含む） | D31: ① ヒアーズミー管理ツールの「一括登録」画面を開く。 ② エラーを含むcsvファイルを選択して「チェック開始」をクリックしてチェック開始確認ダイアログを開く。 ③ チェック開始確認ダイアログの「OK」ボタンをクリックする。 | E31: チェック開始確認ダイアログが閉じ、チェック完了ダイアログが表示されることを確認。 ---------- CSVファイルのチェックが完了しました。 入力エラーのデータがあります。 csvファイルを修正して再度チェックを実施してください。 「OK」 | F31: 高 | G31: 44957 | H31: 神(洋) | I31: OK
B32: =IF($C$12:C32<>"",COUNTA($C$12:C32),"") -> 19 | C32: チェック完了ダイアログ （要確認含む） | D32: ① ヒアーズミー管理ツールの「一括登録」画面を開く。 ② 要確認を含むcsvファイルを選択して「チェック開始」をクリックしてチェック開始確認ダイアログを開く。 ③ チェック開始確認ダイアログの「OK」ボタンをクリックする。 | E32: チェック開始確認ダイアログが閉じ、チェック完了ダイアログが表示されることを確認。 ---------- CSVファイルのチェックが完了しました。 要確認のチェック結果があります。 そのまま登録するデータは一番左の列にチェックを入れて サーバ保存ボタンをクリックしてください。 (チェックしないデータは登録されません) 「OK」 | F32: 高 | G32: 44957 | H32: 神(洋) | I32: OK
B33: =IF($C$12:C33<>"",COUNTA($C$12:C33),"") -> 20 | C33: チェック完了ダイアログ | D33: ① チェック完了ダイアログを開く。 ② チェック完了ダイアログの「OK」ボタンをクリックする。 | E33: チェック完了ダイアログが閉じることを確認。 | F33: 高 | G33: 44956 | H33: 神(洋) | I33: OK
B34: =IF($C$12:C34<>"",COUNTA($C$12:C34),"") -> 21 | C34: 一括登録開始確認ダイアログ | D34: ① ヒアーズミー管理ツールの「一括登録」画面を開く。 ② エラー・要確認を含まないcsvファイルを選択して「チェック開始」を実行する。 ③ 「サーバ保存」ボタンをクリックする。 | E34: 一括登録開始確認ダイアログが表示されることを確認。 ----- 一括登録を開始します。よろしいですか？ 「OK」「キャンセル」 | F34: 高 | G34: 44957 | H34: 神(洋) | I34: OK
B35: =IF($C$12:C35<>"",COUNTA($C$12:C35),"") -> 22 | C35: 一括登録開始確認ダイアログ | D35: ① 一括登録開始確認ダイアログを開く。 ② 一括登録開始確認ダイアログの「OK」ボタンをクリックする。 | E35: 一括登録開始確認ダイアログが閉じ、一括登録完了ダイアログが表示されることを確認。 DBにcsvのデータが追加されていることを確認。 ----- 一括登録が完了しました。 「OK」 | F35: 高 | G35: 44958 | H35: 神(洋) | I35: OK
... B39: =IF($C$12:C39<>"",COUNTA($C$12:C39),"") -> 26 | C39: 変更を保存せず別画面へ | D39: ① ヒアーズミー管理ツールの「一括登録」」画面を開く。 ② 設定内容を任意で変更し、サーバ保存しないまま別画面のメニューをクリックする。 | E39: 保存未完了のメッセージ（ブラウザのメッセージ）が表示されることを確認。 | F39: 高 | G39: 44956 | H39: 神(洋) | I39: OK
B40: =IF($C$12:C40<>"",COUNTA($C$12:C40),"")
B41: サーバ結果正常以外
B42: =IF($C$12:C42<>"",COUNTA($C$12:C42),"") -> 27 | C42: チェック用データ取得 （コマンド：REQ_SEL_MASTER_FOR_USER_IMPORT） | D42: ① ヒアーズミー管理ツールの「一括登録」画面を開く。 ② DBテーブル「iw_classtbl」をリネームする。 ② 任意のcsvファイルを選択し、チェックを実行する。 | E42: サーバ処理エラーのアラートが表示されることを確認。 ------- サーバ処理でエラーが発生しました。 (REQ_SEL_MASTER_FOR_USER_IMPORT) | F42: 高 | G42: 44959 | H42: 神(洋) | I42: NG→OK
B43: =IF($C$12:C43<>"",COUNTA($C$12:C43),"") -> 28 | C43: チェック用データ取得 （コマンド：REQ_SEL_MASTER_FOR_USER_IMPORT） | D43: ① ヒアーズミー管理ツールの「一括登録」画面を開く。 ② サーバAPIを停止する。 ③ 任意のcsvファイルを選択し、チェックを実行する。 | E43: サーバ通信エラーのアラートが表示されることを確認。 ------- サーバとの接続でエラーが発生しました (REQ_SEL_MASTER_FOR_USER_IMPORT/エラー情報) | F43: 高 | G43: 44959 | H43: 神(洋) | I43: OK
...

Sheet アカウント作成ツール
AB1: =SUM(H4,K4,N4,Q4,T4) -> 8
B2: システム名 | C2: ヒアーズミー(ver2.7) | D2: ■ヒアーズミーログイン画面(結合試験環境) | J2: 対象外数 | K2: =COUNTIF(J:J,"★") -> 0 | M2: 対象外数 | N2: =COUNTIF(M:M,"★") -> 0 | S2: 対象外数 | T2: =COUNTIF(S:S,"★") -> 0 | V2: 対象外数 | W2: =COUNTIF(V:V,"★") -> 0 | Y2: 対象外数 | Z2: =COUNTIF(Y:Y,"★") -> 0 | AB2: =SUM(H5,K5,N5,Q5,T5) -> 0
B3: 試験工程 | C3: 結合試験 | D3: https://heresme.micros-america.com/ | J3: 実施数 | K3: =SUM($F$4:$F$6)-K2 -> 8 | M3: 実施数 | N3: =SUM($F$4:$F$6)-N2 -> 8 | S3: 実施数 | T3: =SUM($F$4:$F$6)-T2 -> 8 | V3: 実施数 | W3: =SUM($F$4:$F$6)-W2 -> 8 | Y3: 実施数 | Z3: =SUM($F$4:$F$6)-Z2 -> 8 | AB3: =SUM(H6,K6,N6,Q6,T6) -> 0
B4: 試験項目名 | C4: アカウント作成ツール | E4: 高 | F4: =COUNTIF($F$12:$F$176, "高") -> 8 | H4: =COUNTIFS($F12:$F176,"高",I12:I176,"OK")+COUNTIFS($F12:$F176,"高",I12:I176,"NG→OK") -> 8 | I4: =COUNTIFS($F12:$F176,"高",I12:I176,"NG") -> 0 | K4: =COUNTIFS($F12:$F176,"高",L12:L176,"OK") -> 0 | L4: =COUNTIFS($F12:$F176,"高",L12:L176,"NG") -> 0 | N4: =COUNTIFS($F12:$F176,"高",O12:O176,"OK")+COUNTIFS($F12:$F176,"高",O12:O176,"NG→OK") -> 0 | O4: =COUNTIFS($F12:$F176,"高",O12:O176,"NG") -> 0 | Q4: =COUNTIFS($F12:$F176,"高",R12:R176,"OK") -> 0 | R4: =COUNTIFS($F12:$F176,"高",R12:R176,"NG") -> 0 | T4: =COUNTIFS($F12:$F176,"高",U12:U176,"OK") -> 0 | U4: =COUNTIFS($F12:$F176,"高",U12:U176,"NG") -> 0 | W4: =COUNTIFS($F12:$F176,"高",X12:X176,"OK")+COUNTIFS($F12:$F176,"高",X12:X176,"NG→OK") -> 0 | X4: =COUNTIFS($F12:$F176,"高",X12:X176,"NG") -> 0 | Z4: =COUNTIFS($F12:$F176,"高",AA12:AA176,"OK") -> 0 | AA4: =COUNTIFS($F12:$F176,"高",AA12:AA176,"NG") -> 0 | AB4: =SUM(I4,L4,O4,R4,U4) -> 0
B5: 作成者 | C5: 神 洋子 | D5: ■試験実施バージョン | E5: 中 | F5: =COUNTIF($F$12:$F$176, "中") -> 0 | H5: =COUNTIFS($F12:$F176,"中",I12:I176,"OK") -> 0 | I5: =COUNTIFS($F12:$F176,"中",I12:I176,"NG") -> 0 | K5: =COUNTIFS($F12:$F176,"中",L12:L176,"OK") -> 0 | L5: =COUNTIFS($F12:$F176,"中",L12:L176,"NG") -> 0 | N5: =COUNTIFS($F12:$F176,"中",O12:O176,"OK")+COUNTIFS($F12:$F176,"中",O12:O176,"NG→OK") -> 0 | O5: =COUNTIFS($F12:$F176,"中",O12:O176,"NG") -> 0 | Q5: =COUNTIFS($F12:$F176,"中",R12:R176,"OK") -> 0 | R5: =COUNTIFS($F12:$F176,"中",R12:R176,"NG") -> 0 | T5: =COUNTIFS($F12:$F176,"中",U12:U176,"OK") -> 0 | U5: =COUNTIFS($F12:$F176,"中",U12:U176,"NG") -> 0 | W5: =COUNTIFS($F12:$F176,"中",X12:X176,"OK") -> 0 | X5: =COUNTIFS($F12:$F176,"中",X12:X176,"NG") -> 0 | Z5: =COUNTIFS($F12:$F176,"中",AA12:AA176,"OK") -> 0 | AA5: =COUNTIFS($F12:$F176,"中",AA12:AA176,"NG") -> 0 | AB5: =SUM(I5,L5,O5,R5,U5) -> 0
B6: 作成日 | C6: 44938 | D6: Chrome→★ 、 Firefox→★ | E6: 低 | F6: =COUNTIF($F$12:$F$176, "低") -> 0 | H6: =COUNTIFS($F12:$F176,"低",I12:I176,"OK") -> 0 | I6: =COUNTIFS($F12:$F176,"低",I12:I176,"NG") -> 0 | K6: =COUNTIFS($F12:$F176,"低",L12:L176,"OK") -> 0 | L6: =COUNTIFS($F12:$F176,"低",L12:L176,"NG") -> 0 | N6: =COUNTIFS($F12:$F176,"低",O12:O176,"OK") -> 0 | O6: =COUNTIFS($F12:$F176,"低",O12:O176,"NG") -> 0 | Q6: =COUNTIFS($F12:$F176,"低",R12:R176,"OK") -> 0 | R6: =COUNTIFS($F12:$F176,"低",R12:R176,"NG") -> 0 | T6: =COUNTIFS($F12:$F176,"低",U12:U176,"OK") -> 0 | U6: =COUNTIFS($F12:$F176,"低",U12:U176,"NG") -> 0 | W6: =COUNTIFS($F12:$F176,"低",X12:X176,"OK") -> 0 | X6: =COUNTIFS($F12:$F176,"低",X12:X176,"NG") -> 0 | Z6: =COUNTIFS($F12:$F176,"低",AA12:AA176,"OK") -> 0 | AA6: =COUNTIFS($F12:$F176,"低",AA12:AA176,"NG") -> 0 | AB6: =SUM(I6,L6,O6,R6,U6) -> 0
D7: IE→★ 、 Edge(chronium)→★
C8: 試験項目 | G8: Webブラウザ | V8: スマホアプリ
G9: Chrome | J9: Firefox | M9: edge(Chronium) | P9: edge(旧) | S9: IE | V9: Android | Y9: iOS
B10: No | C10: 試験条件 | D10: 試験手順 | E10: 確認内容 | F10: 優先度 | G10: 日付 | H10: 実施者 | I10: 結果 | J10: 日付 | K10: 実施者 | L10: 結果 | M10: 日付 | N10: 実施者 | O10: 結果 | P10: 日付 | Q10: 実施者 | R10: 結果 | S10: 日付 | T10: 実施者 | U10: 結果 | V10: 日付 | W10: 実施者 | X10: 結果 | Y10: 日付 | Z10: 実施者 | AA10: 結果
B11: 新規アカウント（company_id=0000000019）
B12: =IF($C$12:C12<>"",COUNTA($C$12:C12),"") -> 1 | C12: アカウント作成 | D12: ① アカウント作成ツールの「ヒアーズミー」画面を開く。 ② 任意の情報でアカウンを作成する。 | E12: 正常にログインできることを確認。 DB「iw_ipmanagetbl」にデータが作成されていることを確認。 | F12: 高 | G12: 44942 | H12: 神(洋) | I12: OK
B13: =IF($C$12:C13<>"",COUNTA($C$12:C13),"") -> 2 | C13: ver2.7新規アカウント →IP制限機能を利用 | D13: ① No1を実施する。 ② ①で作成したアカウントでヒアーズミー管理ツールにログインし、「セキュリティ」画面を開く。 ③ 任意の情報に変更して「サーバ保存」を実行する。 | E13: ②実施後、「ヒアーズミーにアクセスするIPアドレスを制限」チェックボックスがOFF、IPリストが空であることを確認。 ③実施後、入力した内容にDBが更新されることを確認。 | F13: 高 | G13: 44956 | H13: 神(洋) | I13: OK
B14: =IF($C$12:C14<>"",COUNTA($C$12:C14),"") -> 3 | C14: ver2.7新規アカウント →一括登録機能を利用 | D14: ① No1(またはNo2)を実施する。 ② ①で作成したアカウントでヒアーズミー管理ツールにログインし、「一括登録」画面を開く。 ③ 任意のcsvファイルでユーザ一括登録を実行する。（「データ（一括登録）」シート【3】一括登録No4のcsvファイルを使用） | E14: csvファイルに記載した内容で、役職・拠点・所属・ユーザが登録されることを確認。 | F14: 高 | G14: 44959 | H14: 神(洋) | I14: OK
B15: =IF($C$12:C15<>"",COUNTA($C$12:C15),"") -> 4 | C15: アカウント削除 | D15: ① No1を実施する。 ② ①で作成したアカウントを削除する。 | E15: DB「iw_ipmanagetbl」を含め、すべてのDBテーブルから①で作成した企業情報が削除されていることを確認。 | F15: 高 | G15: 44959 | H15: 神(洋) | I15: OK
B16: =IF($C$12:C16<>"",COUNTA($C$12:C16),"")
B17: 既存アカウント（company_id=0000000017）
B18: =IF($C$12:C18<>"",COUNTA($C$12:C18),"") -> 5 | C18: ～ver2.6.3既存アカウント →IP制限機能を利用 | D18: ① ver2.6.3以前に登録したアカウントでヒアーズミー管理ツールにログインし、「セキュリティ」画面を開く。 ② 任意の情報に変更して「サーバ保存」を実行する。 | E18: ①実施後、「ヒアーズミーにアクセスするIPアドレスを制限」チェックボックスがOFF、IPリストが空であることを確認。 ②実施後、入力した内容にDBが更新されることを確認。 | F18: 高 | G18: 44956 | H18: 神(洋) | I18: OK
B19: =IF($C$12:C19<>"",COUNTA($C$12:C19),"") -> 6 | C19: ～ver2.6.3既存アカウント →一括登録機能を利用 | D19: ① ver2.6.3以前に登録したアカウントでヒアーズミー管理ツールにログインし、「一括登録」画面を開く。 ③ 任意のcsvファイルでユーザ一括登録を実行する。 | E19: csvファイルに記載した内容で、役職・拠点・所属・ユーザが登録されることを確認。 | F19: 高 | G19: 44959 | H19: 神(洋) | I19: OK
B20: =IF($C$12:C20<>"",COUNTA($C$12:C20),"") -> 7 | C20: アカウント削除 | D20: ① ver2.6.3以前に登録したアカウントを削除する。 | E20: DB「iw_ipmanagetbl」を含め、すべてのDBテーブルから①で作成した企業情報が削除されていることを確認。 | F20: 高 | G20: 44959 | H20: 神(洋) | I20: NG→OK
B21: =IF($C$12:C21<>"",COUNTA($C$12:C21),"")
B22: IP制限リセット
B23: =IF($C$12:C23<>"",COUNTA($C$12:C23),"") -> 8 | C23: IP制限リセット ※レビュー指摘で追加 | D23: ① ヒアーズミー管理ツールの「セキュリティ」画面にて、「ヒアーズミーにアクセスするIPアドレスを制限」チェックボックスをON、IPリストに１件以上の許可IPを設定する。 ② アカウント作成ツールにて、①の設定を行った企業の詳細ダイアログを開き、「IP制限をリセット」チェックボックスをONにし、更新する。 ③ ①のアカウントでヒアーズミー管理ツールの「セキュリティ」画面を表示する。 | E23: ②実施後、DB「iw_ipmanagetbl」のIP制限有効設定（enable_flg）が0に更新されており、IPリスト（ip_list）は変更がないことを確認する。 ③実施後、「ヒアーズミーにアクセスするIPアドレスを制限」チェックボックスがON、許可IPリストは①で設定した内容で、入力できない状態になっていることを確認。 | F23: 高 | G23: 44956 | H23: 神(洋) | I23: OK
B24: =IF($C$12:C24<>"",COUNTA($C$12:C24),"")
B25: =IF($C$12:C25<>"",COUNTA($C$12:C25),"")
B26: =IF($C$12:C26<>"",COUNTA($C$12:C26),"")
B27: =IF($C$12:C27<>"",COUNTA($C$12:C27),"")
B28: =IF($C$12:C28<>"",COUNTA($C$12:C28),"")
B29: =IF($C$12:C29<>"",COUNTA($C$12:C29),"")
B30: =IF($C$12:C30<>"",COUNTA($C$12:C30),"")
B31: =IF($C$12:C31<>"",COUNTA($C$12:C31),"")

Sheet データ（IP制限機能）
A1: IP制限機能 データバリエーション
B3: 【1】表示
B4: リクエスト元IPアドレス | G4: 14.9.148.97 | J4: ※「セキュリティ」画面内に、接続元IPアドレスが表示されること。
B5: No | C5: 実施条件 | AB5: 確認内容
C6: DB「iw_ipmanagetbl」（IP管理テーブル） | AB6: 管理ツール「セキュリティ」画面
C7: 企業ID | F7: IP制限有効設定 | J7: IP設定可能数 | M7: IPリスト | AB7: ヒアーズミーにアクセス するIPアドレスを制限 (チェックボックス) | AG7: XX個まで (IP設定可能数) | AJ7: 許可するIPアドレス
C8: company_id | F8: enable_flg | J8: ip_max_num | M8: ip_list | AJ8: 名称 | AN8: IPアドレス | AR8: リストの行数
B9: 1 | C9: ログインユーザが 所属する企業 | F9: 0（制限しない） | J9: 20 | M9: {} | AB9: チェックOFF | AG9: 20 | AJ9: (空) | AN9: (空) | AR9: 1
B10: 2 | C10: ログインユーザが 所属する企業 | F10: 1（制限する） | J10: 20 | M10: {14.9.148.97_テストIP} | AB10: チェックON | AG10: 20 | AJ10: テストIP | AN10: 14.9.148.97 | AR10: 2
B11: 3 | C11: ログインユーザが 所属する企業 | F11: 1（制限する） | J11: 10 | M11: {14.9.148.97_本社IPアドレス,192.168.10.*_,128.10.128.1/25_北海道支社_} | AB11: チェックON | AG11: 10 | AJ11: テストIP | AN11: 14.9.148.97 | AR11: 4
AJ12: (空) | AN12: 192.168.10.*
AJ13: 北海道支社 | AN13: 128.10.128.1/25
B14: 4 | C14: ログインユーザが 所属する企業 | F14: 1（制限する） | J14: 20 | M14: {192.168.100.1_IP1,192.168.100.2_IP2,,…,192.168.100.19_IP19,192.168.100.20_IP20,} | AB14: チェックON | AG14: 20 | AJ14: IP1 | AN14: 192.168.100.1 | AR14: 20
M15: (許可IP情報を20個保持) | AJ15: IP2 | AN15: 192.168.100.2 | AR15: ※空き行なし
AJ16: … | AN16: …
AJ17: IP19 | AN17: 192.168.100.19
AJ18: IP20 | AN18: 192.168.100.20
B21: 【2】入力チェック
B22: リクエスト元IPアドレス | G22: 14.9.148.97
B23: No | C23: 実施前 | Q23: 入力値 | AE23: 「サーバ保存」ボタンクリック後
C24: 管理ツール「セキュリティ」画面 | Q24: 管理ツール「セキュリティ」画面
C25: ヒアーズミーにアクセス するIPアドレスを制限 (チェックボックス) | H25: 許可するIPアドレス | Q25: ヒアーズミーにアクセス するIPアドレスを制限 (チェックボックス) | V25: 許可するIPアドレス
I26: 名称 | M26: IPアドレス | W26: 名称 | AA26: IPアドレス
B27: 1 | C27: チェックOFF | H27: 1 | I27: (空) | M27: (空) | Q27: チェックON | V27: 1 | W27: 本社IPアドレス | AA27: 14.9.148.97 | AE27: 保存確認ダイアログを表示
B28: =B27+1 -> 2 | C28: チェックON | H28: 1 | I28: 本社IPアドレス | M28: 14.9.148.97 | Q28: チェックOFF | V28: 1 | W28: 本社IPアドレス | AA28: 14.9.148.97 | AE28: 保存確認ダイアログを表示
B29: =B28+1 -> 3 | C29: チェックON | H29: 1 | I29: 本社IPアドレス | M29: 14.9.148.97 | Q29: チェックON | V29: 1 | W29: (空) | AA29: 14.9.148.97 | AE29: 保存確認ダイアログを表示
B30: =B29+1 -> 4 | C30: チェックON | H30: 1 | I30: (任意) | M30: 14.9.148.97 | Q30: チェックON | V30: 1 | W30: (×ボタンでクリア) | AE30: 保存確認ダイアログを表示
H31: 2 | I31: (任意) | M31: 14.9.148.98 | V31: 2 | W31: (空) | AA31: 14.9.148.98
B32: =B30+1 -> 5 | C32: チェックON | H32: 1 | I32: (任意) | M32: 14.9.148.97 | Q32: チェックON | V32: 1 | W32: (任意) | AA32: 14.9.148.97/32 | AE32: 保存確認ダイアログを表示 | AL32: CIDR値最大
B33: =B32+1 -> 6 | C33: チェックON | H33: 1 | I33: (任意) | M33: 14.9.148.97 | Q33: チェックON | V33: 1 | W33: (任意) | AA33: 14.9.148.0/17 | AE33: 保存確認ダイアログを表示 | AL33: （当初/31としていたが、/31は使用不可とのこと）
B34: =B33+1 -> 7 | C34: チェックON | H34: 1 | I34: (任意) | M34: 14.9.148.97 | Q34: チェックON | V34: 1 | W34: (任意) | AA34: 14.8.0.0/13 | AE34: 保存確認ダイアログを表示 | AL34: https://www.vwnet.jp/mura/OldContents/cidr.htm
B35: =B34+1 -> 8 | C35: チェックON | H35: 1 | I35: (任意) | M35: 14.9.148.97 | Q35: チェックON | V35: 1 | W35: (任意) | AA35: 0.0.0.0/1 | AE35: 保存確認ダイアログを表示
B36: =B35+1 -> 9 | C36: チェックON | H36: 1 | I36: (任意) | M36: 14.9.148.97 | Q36: チェックON | V36: 1 | W36: (任意) | AA36: 14.9.148.* | AE36: 保存確認ダイアログを表示
B37: =B36+1 -> 10 | C37: チェックON | H37: 1 | I37: (任意) | M37: 14.9.148.97 | Q37: チェックON | V37: 1 | W37: (任意) | AA37: 14.9.*.* | AE37: 保存確認ダイアログを表示
B38: =B37+1 -> 11 | C38: チェックON | H38: 1 | I38: (任意) | M38: 14.9.148.97 | Q38: チェックON | V38: 1 | W38: (任意) | AA38: 14.*.*.* | AE38: 保存確認ダイアログを表示
B39: =B38+1 -> 12 | C39: チェックOFF | H39: 1 | I39: (空) | M39: (空) | Q39: チェックON | V39: 1 | W39: (空) | AA39: (空) | AE39: エラーメッセージを表示 （許可IPなし）
B40: =B39+1 -> 13 | C40: チェックON | H40: 1 | I40: (任意) | M40: (任意) | Q40: チェックON | V40: 1 | W40: (任意) | AA40: 14.9.148 (「.」数不正) | AE40: エラーメッセージを表示 （IPアドレス形式エラー）
B41: =B40+1 -> 14 | C41: チェックON | H41: 1 | I41: (任意) | M41: (任意) | Q41: チェックON | V41: 1 | W41: (任意) | AA41: 14.9.148. (最後に「.」がある） | AE41: エラーメッセージを表示 （IPアドレス形式エラー）
B42: =B41+1 -> 15 | C42: チェックON | H42: 1 | I42: (任意) | M42: (任意) | Q42: チェックON | V42: 1 | W42: (任意) | AA42: 14.9.148.98.0 (「.」数不正) | AE42: エラーメッセージを表示 （IPアドレス形式エラー）
B43: =B42+1 -> 16 | C43: チェックON | H43: 1 | I43: (任意) | M43: (任意) | Q43: チェックON | V43: 1 | W43: (任意) | AA43: A.9.148.98 (不正文字) | AE43: エラーメッセージを表示 （IPアドレス形式エラー）
...

Sheet データ（一括登録）
A1: ユーザ一括登録機能 データバリエーション
B3: ■DB登録済みデータ（以下のデータをすべて登録した状態で試験を実施すること）
B4: No | C4: DB「iw_companytbl」（企業情報テーブル） | M4: No | N4: DB「iw_classtbl」（役職情報テーブル）
C5: 企業ID | G5: 登録可能ユーザ数 | N5: 企業ID | R5: 役職ID | U5: 役職名（フル） | Z5: 役職名（表示）
C6: company_id | G6: max_user_num | N6: company_id | R6: class_id | U6: c_name1 | Z6: c_name
B7: 1 | C7: ログインユーザが 所属する企業 | G7: 10 | M7: 1 | N7: ログインユーザが 所属する企業 | R7: 10 | U7: 部長 | Z7: 部長
M8: 2 | N8: ログインユーザが 所属する企業 | R8: 11 | U8: 一般社員 | Z8: 社員
B10: No | C10: DB「iw_sectiontbl」（拠点情報テーブル） | S10: No | T10: DB「iw_grouptbl」（所属情報テーブル）
C11: 企業ID | G11: 拠点ID | J11: 拠点名 | O11: 表示順 | T11: 企業ID | X11: 所属ID | AA11: 所属名 | AF11: 拠点ID | AI11: 表示順
C12: company_id | G12: section_id | J12: s_name | O12: vieworder | T12: company_id | X12: group_id | AA12: g_name | AF12: section_id | AI12: vieworder
B13: 1 | C13: ログインユーザが 所属する企業 | G13: 10 | J13: 拠点１ | O13: 1 | S13: 1 | T13: ログインユーザが 所属する企業 | X13: 101 | AA13: 所属１－１ | AF13: 10 | AI13: 1
B14: 2 | C14: ログインユーザが 所属する企業 | G14: 20 | J14: 拠点２ | O14: 2 | S14: 2 | T14: ログインユーザが 所属する企業 | X14: 102 | AA14: 所属１－２ | AF14: 10 | AI14: 2
B15: 3 | C15: ログインユーザが 所属する企業 | G15: 30 | J15: 拠点３ | O15: 3 | S15: 3 | T15: ログインユーザが 所属する企業 | X15: 201 | AA15: 所属２－１ | AF15: 20 | AI15: 3
S16: 4 | T16: ログインユーザが 所属する企業 | X16: 301 | AA16: 所属３－１ | AF16: 30 | AI16: 4
S17: 5 | T17: ログインユーザが 所属する企業 | X17: 302 | AA17: 所属１－１ | AF17: 30 | AI17: 5 | AL17: ※所属名が重複するが拠点が異なる
B19: No | C19: DB「iw_usertbl」（ユーザ情報テーブル） ※以下にない項目は任意
C20: 企業ID | G20: ユーザID | K20: 社員ID | N20: 社員名 | S20: メールアドレス | X20: パスワード | AB20: 役職ID | AE20: 拠点ID | AH20: 所属ID | AK20: 管理者 | AN20: 表示順 | AQ20: テレワークフラグ | AU20: アバターURL | AX20: 社員名(かな) | BC20: 勤怠管理
C21: company_id | G21: user_id | K21: staff_id | N21: name | S21: mail | X21: passwd | AB21: class | AE21: section | AH21: group_id | AK21: admin_flg | AN21: vieworder | AQ21: telework_flg | AU21: avatar | AX21: name_phonetic | BC21: attendance_flg
B22: 1 | C22: ログインユーザが 所属する企業 | G22: 一意のID | K22: 1 | N22: ミクロス 太郎 | S22: t.mic_test2-7@test.co.jp | X22: (任意) | AB22: 10 | AE22: 10 | AH22: 101 | AK22: 1 | AN22: 1 | AQ22: (任意) | AU22: (任意) | AX22: みくろす たろう | BC22: 1
B23: 2 | C23: ログインユーザが 所属する企業 | G23: 一意のID | K23: 2 | N23: ミクロス 花子 | S23: h.mic_test2-7@test.co.jp | X23: (任意) | AB23: 11 | AE23: 10 | AH23: 101 | AK23: 0 | AN23: 2 | AQ23: (任意) | AU23: (任意) | BC23: 1
B24: 3 | C24: ログインユーザが 所属する企業 | G24: 一意のID | K24: 3 | N24: ミクロス 次郎 | S24: j.mic_test2-7@test.co.jp | X24: (任意) | AB24: 11 | AE24: 10 | AH24: 102 | AK24: 0 | AN24: 3 | AQ24: (任意) | AU24: (任意) | AX24: みくろす じろう | BC24: 0
B25: 4 | C25: ログインユーザが 所属する企業 | G25: 一意のID | K25: 4 | N25: ミクロス 三郎 | S25: s.mic_test2-7@test.co.jp | X25: (任意) | AB25: 10 | AE25: 20 | AH25: 201 | AK25: 1 | AN25: 4 | AQ25: (任意) | AU25: (任意) | AX25: みくろす さぶろう | BC25: 0
B27: No | C27: DB「iw_maintbl」（行先情報テーブル） ※以下にない項目は任意
C28: 企業ID | G28: ユーザID | K28: 社員ID | N28: 社員名 | S28: 役職ID
C29: company_id | G29: user_id | K29: staff_id | N29: name | S29: class
B30: 1 | C30: ログインユーザが 所属する企業 | G30: 一意のID | K30: 1 | N30: ミクロス 太郎 | S30: 10
B31: 2 | C31: ログインユーザが 所属する企業 | G31: 一意のID | K31: 2 | N31: ミクロス 花子 | S31: 11
B32: 3 | C32: ログインユーザが 所属する企業 | G32: 一意のID | K32: 3 | N32: ミクロス 次郎 | S32: 11
B33: 4 | C33: ログインユーザが 所属する企業 | G33: 一意のID | K33: 4 | N33: ミクロス 三郎 | S33: 10
B36: 【1】ファイル選択
B37: No | C37: 「ファイルを選択」ボタン 選択するファイルの拡張子 | H37: 結果
B39: 1 | C39: .csv | H39: 選択したファイル名を表示 「チェック開始」ボタンが青
B40: =B39+1 -> 2 | C40: .CSV | H40: 選択したファイル名を表示 「チェック開始」ボタンが青
B41: =B40+1 -> 3 | C41: .Csv | H41: 選択したファイル名を表示 「チェック開始」ボタンが青
B42: =B41+1 -> 4 | C42: .xlsx | H42: エラーダイアログを表示 (csvファイルを選択してください) 「チェック開始」ボタンがグレー
B43: =B42+1 -> 5 | C43: .txt | H43: エラーダイアログを表示 (csvファイルを選択してください) 「チェック開始」ボタンがグレー
B45: 【2】csvファイルチェック
B46: No | C46: csvファイルのデータ | AW46: → 「チェック開始」 クリック後 | AZ46: チェック結果
C47: (1) | F47: (2) | K47: (3) | P47: (4) | U47: (5) | Z47: (6) | AE47: (7) | AK47: (8) | AN47: (9) | AQ47: (10) | AT47: (11) | AZ47: ※メッセージ | BC47: データ表 （各列にはcsvに記載のデータがそのまま表示される） | BQ47: 一括登録ボタン
C48: 社員ID | F48: 社員名 | K48: 社員名(かな) | P48: 役職 | U48: 拠点 | Z48: 所属 | AE48: メールアドレス | AK48: パスワード | AN48: 管理者 | AQ48: 勤怠管理 | AT48: ※範囲外 | BC48: チェックボックス | BG48: 結果 | BI48: エラー表示の列名 | BM48: 要確認の列名
...
